Workbook

Sheet COVER
A1: Indoore MDMS — Consumer Master Data Manual Test Pack
A2: Screen: Master Data → Consumer Data | Drill-down: Consumer Dashboard + DTR Dashboard | URL: https://indore.bestinfra.app | Role: Super Admin
A4: Field | B4: Value
A5: Module | B5: Master Data / Consumer Data (one pack — not a separate Consumer Overview or DTR Overview file)
A6: Coverage rule | B6: Same depth as Consumer Overview + DTR Overview packs: list, filters, ledger, columns, then Consumer Dashboard widgets AND DTR Dashboard widgets reached from this grid.
A7: View rule | B7: Row View (eye) MUST open Consumer Dashboard for that IVRS/meter — never a different consumer.
A8: DTR rule | B8: DTR Code on the grid MUST open (or lead to) /dtr/{code} for that transformer — never Consumer Dashboard.
A9: Download rule | B9: Download / chart icons export a file and must NOT navigate away.
A10: Filter rule | B10: Apply Filters ANDs criteria. Reset Filters clears search, dropdowns, and All/Online/Offline. Empty search ≠ empty filter copy.
A11: Ledger rule | B11: Validate does not insert or update master rows. .xlsx only, max 200 MB. Merge vs Override blank-cell preview must differ.
A12: Total cases | B12: 120
A13: Baseline date | B13: 09-Sep-2026 screenshots (126,743 consumers · Babulal Nandram · meter 88017671)
A14: Status default | B14: Not Executed
A15: Automation | B15: See AUTOMATION-SCOPE — API suite vs UI click. Column Auto Status on TEST-CASES.
A16: Defects | B16: Log product bugs ONLY on DEFECTS. On TEST-CASES put Defect ID only — do not write bug details in Comments.
A18: How to execute
A19: 1. Login as Super Admin. Open Master Data → Consumer Data. Keep Advanced Filters ON unless the case says otherwise.
A20: 2. For each case, click EXACTLY the target in column Click Target (search, dropdown, radio, Apply, View, chart period, event filter, DTR Code).
A21: 3. On Consumer Dashboard, check header IVRS/meter vs the list row, then every widget named in the case (KPIs, Real-Time, Energy, Events).
A22: 4. On DTR Dashboard, check DTR Code / capacity vs the list row, then Real-Time, Energy, Events — data must not be the previous consumer.
A23: 5. Use browser Back to return. Filters on Consumer Data should still be applied. Do not refresh unless the case says so.
A24: 6. Set Status via dropdown: Pass / Fail / Blocked / Pass with Note / Not Executed.
A25: 7. If live counts differ from SNAPSHOT, still Pass if the list total matches the live footer. Fail on wrong consumer/DTR, missing click, or count mismatch vs the widget.
A26: 8. Defects: log ONLY on DEFECTS (summary, steps, expected, actual). On TEST-CASES enter Defect ID (e.g. DEF-CMD-001). Fail without a Defect ID is incomplete.
A28: Areas in scope (this one workbook)
A29: Area | B29: Type | C29: What to cover
A30: Consumer Data list | B30: Master grid | C30: Search, Advanced Filters, All/Online/Offline, pagination, row View/Edit, Download
A31: Ledger | B31: Bulk Upload modal | C31: Template, Merge/Override, .xlsx, 200 MB, Validate (no write), close
A32: Manage Table Columns | B32: Master + Events | C32: Hide/Show/reorder, locked Consumer Name, Reset defaults, Cancel/X
A33: Consumer Dashboard | B33: Detail /consumers/:id | C33: Header, 12 KPIs, Real-Time Power, Live Load, Energy Consumption, Energy Flow, Meter Events
A34: DTR Dashboard | B34: Detail /dtr/:code | C34: Stats, Real-Time Power, Power Triangle, Energy Flow, Energy Consumption, Meter Events, capacity
A35: Parity | B35: Cross-screen | C35: Same IVRS/meter/DTR/hierarchy on list ↔ consumer page ↔ DTR page; Back keeps filters

Sheet AUTOMATION-SCOPE
A1: Consumer Master Data — Automation scope (API already in this repo vs still-manual UI)
A2: This framework automates HTTP APIs (Playwright). UI onclick / Ledger picker / dashboard widgets stay Gap (UI) until a UI suite is added. Partial = API proves list/filters; tester still clicks Apply/View.
A4: Counts from TEST-CASES column Auto Status (M)
A5: Metric | B5: Count | C5: Meaning
A6: Automated (API) | B6: =COUNTIF('TEST-CASES'!M8:M400,"Automated (API)") | C6: Data already asserted in Playwright API/DB tests
A7: Partial | B7: =COUNTIF('TEST-CASES'!M8:M400,"Partial") | C7: API covers list/filters; UI click still manual
A8: Gap (API) | B8: =COUNTIF('TEST-CASES'!M8:M400,"Gap (API)") | C8: Add a Playwright API case (priority for this repo)
A9: Gap (UI) | B9: =COUNTIF('TEST-CASES'!M8:M400,"Gap (UI)") | C9: Needs UI automation — out of current API framework
A10: Total classified | B10: =B6+B7+B8+B9 | C10: Must equal 120 test cases
A13: Area → API map
A14: Widget | B14: UI click | C14: Data API (counts) | D14: Drilldown API (related records) | E14: Spec | F14: Auto status | G14: Gap / next action
A15: Consumer Data grid | B15: Search / page / filter Apply | C15: GET /indore/master-data/consumer-master-data | D15: GET /indore/master-data/consumer-master-data filtered query | E15: src/modules/MASTER-DATA/tests/consumer-master.spec.ts | npm run test:master-data | F15: Partial | G15: API proves page/q/filters; UI Apply/Reset still manual
A16: Advanced Filters | B16: Apply / Reset / radios | C16: GET /indore/master-data/consumer-master-data + lookup APIs | D16: GET /indore/master-data/consumer-master-data | E16: src/modules/MASTER-DATA/tests/consumer-master.spec.ts | npm run test:master-data | F16: Partial | G16: Lookups and filtered list are API; cascade UI is Gap (UI)
A17: Ledger / Bulk Upload | B17: Validate File | C17: POST /indore/master-data/bulk-upload-consumers (and Ledger validate) | D17: Validate preview (no write) | E17: src/modules/MASTER-DATA/tests/bulk-upload-consumers.spec.ts | F17: Partial | G17: File picker, Merge/Override copy, 200 MB client checks are UI
A18: Header Download | B18: Export icon | C18: Consumer master export job | D18: Filtered xlsx | E18: src/modules/MASTER-DATA/tests/master-data.contract.spec.ts | F18: Gap (API) | G18: Add export-job assertion; UI click remains Gap (UI)
A19: Manage Table Columns | B19: Hide / Show / Apply | C19: — | D19: — | E19: — | F19: Gap (UI) | G19: Local table prefs — UI automation
A20: Consumer Dashboard | B20: View (eye) → /consumers/:id | C20: Consumer detail APIs (KPIs, RT power, energy, events) | D20: Same consumer id | E20: CONTRIBUTING: consumers module if present | F20: Gap (UI) | G20: No click-through UI suite yet; detail APIs may exist under CONSUMERS
A21: DTR Dashboard | B21: DTR Code → /dtr/:code | C21: DTR detail APIs (stats, RT power, energy, events) | D21: Same DTR code | E21: DASHBOARD dtr* specs cover fleet Overview, not this individual page | F21: Gap (UI) | G21: Individual DTR page is Gap (UI); fleet Overview is a different pack (IND-DTO)
A22: Meter Events (consumer + DTR) | B22: Search / status / date / download | C22: Events APIs | D22: Filtered event list | E22: — | F22: Gap (UI) | G22: Duration math and column modal are UI
A23: Energy Consumption / Energy Flow | B23: Period dropdown + download | C23: Energy graph APIs | D23: Period series | E23: — | F23: Gap (UI) | G23: Hourly→Yearly switch is UI
A26: Already automated — run these
A27: Coverage | B27: Endpoint | C27: Spec file | D27: Command | E27: Status
A28: Consumer Master Data paged list | B28: GET /indore/master-data/consumer-master-data | C28: src/modules/MASTER-DATA/tests/consumer-master.spec.ts | D28: npm run test:master-data | E28: Automated (API)
A29: Consumer Master contract snapshot | B29: GET /indore/master-data/consumer-master-data | C29: src/modules/MASTER-DATA/tests/master-data.contract.spec.ts | D29: npm run test:master-data | E29: Automated (API)
A30: Bulk upload consumers | B30: POST /indore/master-data/bulk-upload-consumers (and Ledger validate) | C30: src/modules/MASTER-DATA/tests/bulk-upload-consumers.spec.ts | D30: npm run test:master-data | E30: Automated (API)
A33: Gaps to automate next (priority)
A34: Priority | B34: Layer | C34: What to add | D34: Where | E34: Manual cases
A35: P1 | B35: UI | C35: View (eye) opens Consumer Dashboard with matching IVRS/meter | D35: Playwright UI on /master-data/consumer-master-data | E35: IND-CMD-0038, 0066, 0120
A36: P1 | B36: UI | C36: DTR Code opens individual DTR Dashboard | D36: Playwright UI /dtr/:code from master grid | E36: IND-CMD-0104, 0108–0112
A37: P1 | B37: API | C37: Filtered consumer-master export job row count = pagination.total | D37: MASTER-DATA export API spec | E37: IND-CMD-0063, 0065
A38: P2 | B38: UI | C38: Ledger client checks: type, 200 MB, Merge vs Override blanks | D38: Playwright UI Ledger modal | E38: IND-CMD-0050–0062
A39: P2 | B39: UI | C39: Meter Events duration = restored − occurred; Pending Restored At = — | D39: Consumer + DTR events tables | E39: IND-CMD-0091–0096, 0112

Sheet COVERAGE-MATRIX
A1: Coverage matrix — Y = must execute | EXP = export only (must not navigate) | N/A = not on this control | Types: Positive / Negative / Edge / UI
A2: Execute every Y cell. Consumer Dashboard and DTR Dashboard are in THIS pack (not a second Excel). Empty search and empty filter use different copy.
A4: Area / widget | B4: Page load / layout | C4: Search / filter | D4: Apply / Reset | E4: Pagination / columns | F4: View / navigation | G4: Chart / period | H4: Empty / invalid | I4: Download / export | J4: Zero / missing data | K4: Y count | L4: Notes
A5: Consumer Data list | B5: Y | C5: Y | D5: Y | E5: Y | F5: Y | G5: N/A | H5: Y | I5: EXP | J5: Y | K5: =COUNTIF(B5:J5,"Y") | L5: 126,743 baseline
A6: Advanced Filters | B6: Y | C6: Y | D6: Y | E6: N/A | F6: N/A | G6: N/A | H6: Y | I6: N/A | J6: Y | K6: =COUNTIF(B6:J6,"Y") | L6: Hierarchy cascade + radios
A7: Ledger / Bulk Upload | B7: Y | C7: N/A | D7: N/A | E7: N/A | F7: N/A | G7: N/A | H7: Y | I7: EXP | J7: Y | K7: =COUNTIF(B7:J7,"Y") | L7: Validate ≠ write
A8: Manage Columns (grid) | B8: Y | C8: N/A | D8: Y | E8: Y | F8: N/A | G8: N/A | H8: Y | I8: N/A | J8: Y | K8: =COUNTIF(B8:J8,"Y") | L8: Consumer Name locked
A9: Consumer Dashboard header | B9: Y | C9: N/A | D9: N/A | E9: N/A | F9: Y | G9: N/A | H9: Y | I9: EXP | J9: N/A | K9: =COUNTIF(B9:J9,"Y") | L9: IVRS + Connected
A10: Consumer KPI cards (12) | B10: Y | C10: N/A | D10: N/A | E10: N/A | F10: N/A | G10: N/A | H10: N/A | I10: N/A | J10: Y | K10: =COUNTIF(B10:J10,"Y") | L10: No previous-month data
A11: Real-Time Power + Live Load | B11: Y | C11: N/A | D11: N/A | E11: N/A | F11: N/A | G11: N/A | H11: Y | I11: EXP | J11: Y | K11: =COUNTIF(B11:J11,"Y") | L11: Y/B = -- ; timestamp parity
A12: Energy Consumption | B12: Y | C12: N/A | D12: N/A | E12: N/A | F12: N/A | G12: Y | H12: Y | I12: EXP | J12: Y | K12: =COUNTIF(B12:J12,"Y") | L12: Hourly→Yearly
A13: Energy Flow | B13: Y | C13: N/A | D13: N/A | E13: N/A | F13: N/A | G13: Y | H13: Y | I13: EXP | J13: Y | K13: =COUNTIF(B13:J13,"Y") | L13: Import/export series
A14: Meter Events (consumer) | B14: Y | C14: Y | D14: Y | E14: Y | F14: N/A | G14: N/A | H14: Y | I14: EXP | J14: Y | K14: =COUNTIF(B14:J14,"Y") | L14: Duration math
A15: DTR Dashboard | B15: Y | C15: N/A | D15: N/A | E15: N/A | F15: Y | G15: Y | H15: Y | I15: EXP | J15: Y | K15: =COUNTIF(B15:J15,"Y") | L15: Same widget family as consumer
A16: Parity list ↔ dashboards | B16: Y | C16: N/A | D16: N/A | E16: N/A | F16: Y | G16: Y | H16: N/A | I16: N/A | J16: N/A | K16: =COUNTIF(B16:J16,"Y") | L16: Meter / DTR / hierarchy
A19: Must-run destinations (from 09-Sep-2026 screenshots)
A20: # | B20: Screen | C20: Target | D20: Baseline (09-Sep-2026)
A21: 1 | B21: Consumer Data | C21: Unfiltered total | D21: 126743
A22: 2 | B22: Consumer Data | C22: Page size 10 → last page | D22: 12675
A23: 3 | B23: Consumer Data | C23: Search Babulal Nandram / IVRS N3968028469 | D23: 1+ match
A24: 4 | B24: Consumer Data | C24: Online / Offline radios | D24: subset of 126743
A25: 5 | B25: Ledger | C25: Validate File without write | D25: .xlsx ≤ 200 MB
A26: 6 | B26: Consumer Dashboard | C26: Header Connected + 12 KPIs | D26: 0.2 kVA / PF -0.97 / ₹0
A27: 7 | B27: Consumer Dashboard | C27: Real-Time Power meter | D27: 88017671
A28: 8 | B28: Consumer Dashboard | C28: Live Load total | D28: 0.08 = 0.04+0.04+0
A29: 9 | B29: Consumer Dashboard | C29: Energy Consumption Hourly | D29: Last 12 Hours 12:00–23:00
A30: 10 | B30: Consumer Dashboard | C30: Energy Flow Hourly | D30: Last 6 Hours 1 Dec 2025
A31: 11 | B31: Meter Events | C31: Unfiltered rows | D31: 5 of 5
A32: 12 | B32: Meter Events | C32: Pending | D32: 2
A33: 13 | B33: Meter Events | C33: Restored | D33: 3
A34: 14 | B34: DTR Dashboard | C34: DTR from grid (e.g. MM521) | D34: /dtr/{code}
A35: 15 | B35: Parity | C35: Same meter on list, consumer page, DTR events | D35: 88017671
A38: Type mix (from TEST-CASES column K)
A39: Type | B39: Count formula | C39: Meaning
A40: Positive | B40: =COUNTIF('TEST-CASES'!K8:K400,"Positive") | C40: Happy path
A41: Negative | B41: =COUNTIF('TEST-CASES'!K8:K400,"Negative") | C41: Invalid / empty / reject
A42: Edge | B42: =COUNTIF('TEST-CASES'!K8:K400,"Edge") | C42: Boundary / missing history / 1-phase
A43: UI | B43: =COUNTIF('TEST-CASES'!K8:K400,"UI") | C43: Layout / cursor / default selection
A44: Total | B44: =B40+B41+B42+B43 | C44: Must equal 120

Sheet LISTS
A1: Status | B1: Priority | C1: Type | D1: Auto Status | E1: Automation Scope | F1: Defect Status | G1: Defect Severity | H1: Defect Priority
A2: Not Executed | B2: Critical | C2: Positive | D2: Automated (API) | E2: API automated | F2: New | G2: Critical | H2: P0
A3: Pass | B3: High | C3: Negative | D3: Partial | E3: API + UI click | F3: Open | G3: High | H3: P1
A4: Fail | B4: Medium | C4: Edge | D4: Gap (API) | E4: API gap | F4: In Progress | G4: Medium | H4: P2
A5: Blocked | B5: Low | C5: UI | D5: Gap (UI) | E5: UI only | F5: Fixed | G5: Low | H5: P3
A6: Pass with Note | F6: Verified
F7: Closed
F8: Rejected
F9: Deferred

Sheet DEFECTS
A1: Indoore MDMS — Consumer Master Data — Defect log
A2: SOURCE OF TRUTH: log every product defect HERE only. On TEST-CASES enter Defect ID (column R). Do not write bug details in TEST-CASES Comments.
A3: Open / New | D3: In Progress | G3: Fixed / Verified | J3: Closed | M3: Total logged
A4: =COUNTIF(J8:J37,"Open")+COUNTIF(J8:J37,"New") | D4: =COUNTIF(J8:J37,"In Progress") | G4: =COUNTIF(J8:J37,"Fixed")+COUNTIF(J8:J37,"Verified") | J4: =COUNTIF(J8:J37,"Closed") | M4: =COUNTA(D8:D37)
A5: How: pick next blank DEF-CMD-xxx row → fill Summary / Steps / Expected / Actual / Severity / Status. Then put that ID on every failed TEST-CASES row. Related cases share one Defect ID.
A7: Defect ID | B7: Linked Test Case ID | C7: Widget / Feature | D7: Summary | E7: Steps to Reproduce | F7: Expected Result | G7: Actual Result | H7: Severity | I7: Priority | J7: Defect Status | K7: Environment | L7: Found By | M7: Found Date | N7: Evidence / Screenshot | O7: Comments
A8: DEF-CMD-001 | B8: IND-CMD-0078, IND-CMD-0080, IND-CMD-0081, IND-CMD-0087 | C8: Real-Time Power Metrics / Live Load Profile / Energy Flow | D8: Last-communication timestamps disagree by a calendar day between Real-Time Power Metrics and Live Load / Energy Flow | E8: 1. Login as Super Admin on https://indore.bestinfra.app 2. Open Master Data → Consumer Data 3. Open Consumer Dashboard for Babulal Nandram (IVRS N3968028469) 4. Read Real-Time Power Metrics header timestamp 5. Read Live Load Profile Last Communication 6. Read Energy Flow subtitle date | F8: If all three stamps are 'last packet / last communication', they match to the same minute (or are clearly labelled as different metrics). Energy Flow 'Last 6 Hours' date aligns with the live last-communication day. | G8: 09-Sep-2026: Real-Time Power Metrics shows 30th Nov 2025, 11:45 PM (meter 88017671). Live Load Profile Last Communication is 1st Dec 2025, 11:46 PM. Energy Flow subtitle is Last 6 Hours · 18:00–23:00, 1 Dec 2025. Unexplained 1-day (and ~24h) split between the header and the lower widgets. | H8: High | I8: P1 | J8: Open | K8: Live https://indore.bestinfra.app — Super Admin | L8: QA (screenshot review) | M8: 46273.771 | N8: Consumer Dashboard screenshots 09-Sep-2026 (Real-Time Power + Live Load + Energy Flow)
A9: DEF-CMD-002 | B9: IND-CMD-0091, IND-CMD-0096, IND-CMD-0077 | C9: Meter Events | D9: Restored Power failure row shows Duration 6s and Status Restored but Restored At is blank | E9: 1. Open Consumer Dashboard for Babulal Nandram 2. Scroll to Meter Events 3. Inspect row 1: Event Code 7048 Power failure, Occurred 1st Nov 2025 08:20 PM, Status Restored | F9: Restored events always show Restored At. Duration = Restored At − Occurred On. Pending events use — in Restored At and 0s duration. | G9: 09-Sep-2026: Row 1 Status=Restored, Duration=6s, Restored At blank (not —). Other Restored rows (16 Jul, 9 Jul) do show Restored At. Inconsistent Restored At rendering on the same table. | H9: Medium | I9: P2 | J9: Open | K9: Live https://indore.bestinfra.app — Super Admin | L9: QA (screenshot review) | M9: 46273.771 | N9: Meter Events screenshot 09-Sep-2026 (5 rows, meter 88017671)
A10: DEF-CMD-003
A11: DEF-CMD-004
A12: DEF-CMD-005
A13: DEF-CMD-006
A14: DEF-CMD-007
A15: DEF-CMD-008
A16: DEF-CMD-009
A17: DEF-CMD-010
A18: DEF-CMD-011
A19: DEF-CMD-012
A20: DEF-CMD-013
A21: DEF-CMD-014
... A37: DEF-CMD-030

Sheet TEST-CASES
A1: Indoore MDMS — Consumer Master Data — Manual Test Cases (includes Consumer Dashboard + DTR Dashboard)
A2: One pack (same format as Consumer Overview / DTR Overview) | Defects: log on DEFECTS only, put Defect ID here
A3: ="Total cases: 120 | Executed: "&COUNTIF(I8:I500,"<>Not Executed")-COUNTIF(I8:I500,"")&" | Pass: "&COUNTIF(I8:I500,"Pass")&" | Fail: "&COUNTIF(I8:I500,"Fail")&" | Blocked: "&COUNTIF(I8:I500,"Blocked")&" | Pass %: "&IF(COUNTIF(I8:I500,"Pass")+COUNTIF(I8:I500,"Fail")+COUNTIF(I8:I500,"Pass with Note")+COUNTIF(I8:I500,"Blocked")=0,"—",TEXT(COUNTIF(I8:I500,"Pass")/(COUNTIF(I8:I500,"Pass")+COUNTIF(I8:I500,"Fail")+COUNTIF(I8:I500,"Pass with Note")+COUNTIF(I8:I500,"Blocked")),"0%"))
A5: Precondition: Super Admin on https://indore.bestinfra.app — Master Data → Consumer Data — View opens Consumer Dashboard — DTR Code opens DTR Dashboard. Failures: log on DEFECTS, enter Defect ID here only.
A7: Test Case ID | B7: Feature | C7: Click Target | D7: Test Scenario | E7: Test Steps | F7: Test Data | G7: Expected Result | H7: Actual Result | I7: Status | J7: Priority | K7: Type | L7: Automation Scope | M7: Auto Status | N7: API Endpoint | O7: Spec / Command | P7: Tester | Q7: Execution Date | R7: Defect ID | S7: Comments
A8: 1. PAGE LOAD & LAYOUT — CONSUMER MASTER DATA
A9: IND-CMD-0001 | B9: Page Load | C9: Page | D9: Consumer Data page loads with title and breadcrumb | E9: 1. Login as Super Admin on https://indore.bestinfra.app 2. Open Master Data → Consumer Data 3. Confirm title is Consumer Data and Advanced Filters is ON unless the case says otherwise 4. Observe header, breadcrumb, and primary actions | F9: URL: Master Data / Consumer Data | G9: Title 'Consumer Data' is visible. Breadcrumb shows Master Data / Consumer Data. No blank page, stuck spinner, or blocking console error. | I9: Not Executed | J9: Critical | K9: UI | L9: UI only | M9: Gap (UI) | N9: — | O9: Page title / breadcrumb — Playwright UI
A10: IND-CMD-0002 | B10: Layout | C10: Header actions | D10: Bulk Upload and Download buttons render in the header | E10: 1. Login as Super Admin on https://indore.bestinfra.app 2. Open Master Data → Consumer Data 3. Confirm title is Consumer Data and Advanced Filters is ON unless the case says otherwise 4. Look at top-right actions | F10: Buttons: Bulk Upload (green, up arrow), Download (green, down arrow) | G10: Both buttons are visible, labelled, and clickable for Super Admin. Bulk Upload opens Ledger. Download starts an export (does not navigate away). | I10: Not Executed | J10: Critical | K10: UI | L10: UI only | M10: Gap (UI) | N10: — | O10: Bulk Upload + Download header buttons
A11: IND-CMD-0003 | B11: Layout | C11: Advanced Filters panel | D11: Advanced Filters panel is ON and shows all filter controls | E11: 1. Login as Super Admin on https://indore.bestinfra.app 2. Open Master Data → Consumer Data 3. Confirm title is Consumer Data and Advanced Filters is ON unless the case says otherwise 4. Observe the Advanced Filters box | F11: Toggle ON. Controls: Search Consumers, Hierarchy Type, two Select Hierarchy, Meter Type, All Meter Phases, Connection Status, All Categories, Device Manufacturer, Payment Contract, All/Online/Offline, Reset Filters, Apply Filters | G11: All listed controls render. Toggle is green/ON. Reset Filters is outline. Apply Filters is solid green. No overlapping or clipped labels. | I11: Not Executed | J11: Critical | K11: UI | L11: UI only | M11: Gap (UI) | N11: — | O11: Advanced Filters panel layout
A12: IND-CMD-0004 | B12: Layout | C12: Consumer grid | D12: Grid loads first page with pagination for the full master set | E12: 1. Login as Super Admin on https://indore.bestinfra.app 2. Open Master Data → Consumer Data 3. Confirm title is Consumer Data and Advanced Filters is ON unless the case says otherwise 4. Wait for the table to finish loading 5. Read footer pagination | F12: Screenshot baseline 09-Sep-2026 (use live values if different): Showing 1-10 of 126743 · 10 / page · last page 12675 | G12: Ten data rows render. Footer matches live total. Page 1 is selected. Horizontal scrollbar is present for extra columns. No duplicate S.No and no empty skeleton stuck forever. | I12: Not Executed | J12: Critical | K12: Positive | L12: API + UI click | M12: Partial | N12: GET /indore/master-data/consumer-master-data?page=1&limit=10 | pagination.total vs grid | O12: src/modules/MASTER-DATA/tests/consumer-master.spec.ts | npm run test:master-data
A13: IND-CMD-0005 | B13: Cursor | C13: Interactive controls | D13: Clickable controls show pointer cursor | E13: 1. Login as Super Admin on https://indore.bestinfra.app 2. Open Master Data → Consumer Data 3. Confirm title is Consumer Data and Advanced Filters is ON unless the case says otherwise 4. Hover Bulk Upload, Download, search, dropdowns, radios, Apply/Reset, row View/Edit, pagination, column-manage icon | F13: Hover each interactive control | G13: Pointer (hand) cursor on every clickable control. Non-clickable padding/page background stays default cursor. | I13: Not Executed | J13: Medium | K13: UI | L13: UI only | M13: Gap (UI) | N13: — | O13: Pointer cursor
A14: 2. SEARCH CONSUMERS
A15: IND-CMD-0006 | B15: Search | C15: Search Consumers | D15: Search by consumer name returns matching rows | E15: 1. Login as Super Admin on https://indore.bestinfra.app 2. Open Master Data → Consumer Data 3. Confirm title is Consumer Data and Advanced Filters is ON unless the case says otherwise 4. Type Babulal Nandram in Search Consumers 5. Wait for debounce / results | F15: Name: Babulal Nandram | G15: Grid shows matching consumer(s). Pagination total drops to the match count. Row name matches. No unfiltered dump of all consumers. | I15: Not Executed | J15: Critical | K15: Positive | L15: API + UI click | M15: Partial | N15: GET /indore/master-data/consumer-master-data?q=Babulal Nandram | O15: src/modules/MASTER-DATA/tests/consumer-master.spec.ts | npm run test:master-data
A16: IND-CMD-0007 | B16: Search | C16: Search Consumers | D16: Search by IVRS number | E16: 1. Login as Super Admin on https://indore.bestinfra.app 2. Open Master Data → Consumer Data 3. Confirm title is Consumer Data and Advanced Filters is ON unless the case says otherwise 4. Clear search 5. Type N3968028469 | F16: IVRS: N3968028469 | G16: Matching consumer (Babulal Nandram or live equivalent) is listed. IVRS on the dashboard header after View matches the search value. | I16: Not Executed | J16: Critical | K16: Positive | L16: API + UI click | M16: Partial | N16: GET /indore/master-data/consumer-master-data?q=N3968028469 | O16: src/modules/MASTER-DATA/tests/consumer-master.spec.ts | npm run test:master-data
A17: IND-CMD-0008 | B17: Search | C17: Search Consumers | D17: Search by consumer account / CID | E17: 1. Login as Super Admin on https://indore.bestinfra.app 2. Open Master Data → Consumer Data 3. Confirm title is Consumer Data and Advanced Filters is ON unless the case says otherwise 4. Search MML0000205 | F17: CID: MML0000205 | G17: Row with that consumer id is returned. Other Cids are not mixed in. | I17: Not Executed | J17: High | K17: Positive | L17: API + UI click | M17: Partial | N17: GET /indore/master-data/consumer-master-data?q=MML0000205 | O17: src/modules/MASTER-DATA/tests/consumer-master.spec.ts | npm run test:master-data
A18: IND-CMD-0009 | B18: Search | C18: Search Consumers | D18: Search by meter serial number | E18: 1. Login as Super Admin on https://indore.bestinfra.app 2. Open Master Data → Consumer Data 3. Confirm title is Consumer Data and Advanced Filters is ON unless the case says otherwise 4. Search 88017671 | F18: Meter Sl No.: 88017671 | G18: Consumers bound to that meter are listed. Opening the row shows the same meter on Real-Time Power Metrics. | I18: Not Executed | J18: High | K18: Positive | L18: API + UI click | M18: Partial | N18: GET /indore/master-data/consumer-master-data?q=88017671 | O18: src/modules/MASTER-DATA/tests/consumer-master.spec.ts | npm run test:master-data
A19: IND-CMD-0010 | B19: Search | C19: Search Consumers | D19: Unknown keyword shows search empty state | E19: 1. Login as Super Admin on https://indore.bestinfra.app 2. Open Master Data → Consumer Data 3. Confirm title is Consumer Data and Advanced Filters is ON unless the case says otherwise 4. Search ZZZNOMATCH999 | F19: Keyword that cannot match | G19: Empty state title 'No results found'. Description tells the user to adjust search (consumer number, meter number, or name). Clear Search action is available. Pagination is not a fake full list. | I19: Not Executed | J19: High | K19: Negative | L19: API + UI click | M19: Partial | N19: GET /indore/master-data/consumer-master-data?q=ZZZNOMATCH999 (empty page) | O19: src/modules/MASTER-DATA/tests/consumer-master.spec.ts | npm run test:master-data
A20: IND-CMD-0011 | B20: Search | C20: Search Consumers | D20: Special characters do not crash search | E20: 1. Login as Super Admin on https://indore.bestinfra.app 2. Open Master Data → Consumer Data 3. Confirm title is Consumer Data and Advanced Filters is ON unless the case says otherwise 4. Search <script>alert(1)</script> then ' OR 1=1 -- | F20: XSS / SQL-like strings | G20: App does not execute script. No 500/white screen. Either 0 results empty state or escaped literal match. Toast/error is user-safe. | I20: Not Executed | J20: High | K20: Negative | L20: UI only | M20: Gap (UI) | N20: — | O20: XSS / injection in search box
A21: IND-CMD-0012 | B21: Search | C21: Search Consumers | D21: Partial name and case-insensitive search | E21: 1. Login as Super Admin on https://indore.bestinfra.app 2. Open Master Data → Consumer Data 3. Confirm title is Consumer Data and Advanced Filters is ON unless the case says otherwise 4. Search babulal (lowercase, partial) | F21: Partial: babulal | G21: Babulal Nandram (and other Babulal* names if any) appear. Search is not case-sensitive. | I21: Not Executed | J21: Medium | K21: Edge | L21: API + UI click | M21: Partial | N21: GET /indore/master-data/consumer-master-data?q=babulal | O21: src/modules/MASTER-DATA/tests/consumer-master.spec.ts | npm run test:master-data
A22: IND-CMD-0013 | B22: Search | C22: Search Consumers | D22: Names with W/o, titles, and punctuation still match | E22: 1. Login as Super Admin on https://indore.bestinfra.app 2. Open Master Data → Consumer Data 3. Confirm title is Consumer Data and Advanced Filters is ON unless the case says otherwise 4. Search Aabeda Bee 5. Then search W/o Nasir | F22: Grid samples: Aabeda Bee W/o Nasir Ali, Sh.girishchandra Madholal | G22: Both searches return the related rows. Slash and period in the name do not break the query. | I22: Not Executed | J22: Medium | K22: Edge | L22: API + UI click | M22: Partial | N22: GET /indore/master-data/consumer-master-data?q=Aabeda Bee | O22: src/modules/MASTER-DATA/tests/consumer-master.spec.ts | npm run test:master-data
A23: IND-CMD-0014 | B23: Search | C23: Search Consumers | D23: Leading/trailing spaces are trimmed | E23: 1. Login as Super Admin on https://indore.bestinfra.app 2. Open Master Data → Consumer Data 3. Confirm title is Consumer Data and Advanced Filters is ON unless the case says otherwise 4. Search ' Babulal Nandram ' (spaces around) | F23: Padded name | G23: Same results as trimmed search. Spaces do not force empty state. | I23: Not Executed | J23: Medium | K23: Edge | L23: UI only | M23: Gap (UI) | N23: — | O23: Trim spaces in search input
A24: 3. ADVANCED FILTERS — HIERARCHY & DROPDOWNS
A25: IND-CMD-0015 | B25: Hierarchy | C25: Hierarchy Type | D25: Selecting Hierarchy Type enables the next hierarchy dropdown | E25: 1. Login as Super Admin on https://indore.bestinfra.app 2. Open Master Data → Consumer Data 3. Confirm title is Consumer Data and Advanced Filters is ON unless the case says otherwise 4. Open Hierarchy Type 5. Pick a type 6. Open first Select Hierarchy | F25: Cascade: Type → Level 1 → Level 2 | G25: Level 1 options load for the chosen type. Level 2 stays empty or disabled until Level 1 is chosen. No stale options from a previous type. | I25: Not Executed | J25: Critical | K25: Positive | L25: UI only | M25: Gap (UI) | N25: — | O25: Hierarchy Type cascade
A26: IND-CMD-0016 | B26: Hierarchy | C26: Select Hierarchy (Level 1 + 2) | D26: Apply a Circle → Zone path and confirm grid rows match | E26: 1. Login as Super Admin on https://indore.bestinfra.app 2. Open Master Data → Consumer Data 3. Confirm title is Consumer Data and Advanced Filters is ON unless the case says otherwise 4. Set hierarchy so Circle = Indore City Circle and a Zone (e.g. South) 5. Click Apply Filters 6. Scan Circle and Zone columns | F26: Screenshot baseline 09-Sep-2026 (use live values if different): visible Circle column = Indore City Circle; Zones include North/South/West/Central/East | G26: After Apply, every visible row belongs to the selected hierarchy. Pagination total is the filtered count, not 126743 unless that is the live filtered total. | I26: Not Executed | J26: Critical | K26: Positive | L26: API + UI click | M26: Partial | N26: GET /indore/master-data/consumer-master-data + hierarchyLevelId / organisationLookupId / networkLookupId | O26: src/modules/MASTER-DATA/tests/consumer-master.spec.ts | npm run test:master-data
A27: IND-CMD-0017 | B27: Hierarchy | C27: Select Hierarchy (Level 2) | D27: Changing Level 1 clears stale Level 2 | E27: 1. Login as Super Admin on https://indore.bestinfra.app 2. Open Master Data → Consumer Data 3. Confirm title is Consumer Data and Advanced Filters is ON unless the case says otherwise 4. Select Type + Level 1 + Level 2 5. Change Level 1 to a different node | F27: Dependent dropdown | G27: Level 2 value is cleared. New Level 2 options belong to the new parent. Applying without re-picking Level 2 does not send the old child id. | I27: Not Executed | J27: High | K27: Edge | L27: UI only | M27: Gap (UI) | N27: — | O27: Dependent hierarchy clear
A28: IND-CMD-0018 | B28: Meter Type | C28: Meter Type dropdown | D28: Filter by Meter Type Live / Test / All | E28: 1. Login as Super Admin on https://indore.bestinfra.app 2. Open Master Data → Consumer Data 3. Confirm title is Consumer Data and Advanced Filters is ON unless the case says otherwise 4. Select Live, Apply 5. Reset, select Test, Apply 6. Reset to All, Apply | F28: Meter Type: All | Live | Test | G28: Each Apply refreshes the grid. All restores the unscoped meter-type set. No mix of Live rows when Test is applied. | I28: Not Executed | J28: High | K28: Positive | L28: API + UI click | M28: Partial | N28: GET /indore/master-data/consumer-master-data?meterType=live|test|all | O28: src/modules/MASTER-DATA/tests/consumer-master.spec.ts | npm run test:master-data
A29: IND-CMD-0019 | B29: Meter Phase | C29: All Meter Phases | D29: Filter by a single meter phase | E29: 1. Login as Super Admin on https://indore.bestinfra.app 2. Open Master Data → Consumer Data 3. Confirm title is Consumer Data and Advanced Filters is ON unless the case says otherwise 4. Open All Meter Phases 5. Pick 1 PH (or a live phase) 6. Apply Filters 7. Check Phase column | F29: Phase column on the grid | G29: Visible rows match the selected phase. Pagination total equals the phase subset. | I29: Not Executed | J29: High | K29: Positive | L29: API + UI click | M29: Partial | N29: GET /indore/master-data/consumer-master-data meter phase filter | O29: src/modules/MASTER-DATA/tests/consumer-master.spec.ts | npm run test:master-data
A30: IND-CMD-0020 | B30: Connection Status | C30: Connection Status | D30: Filter by Connection Status | E30: 1. Login as Super Admin on https://indore.bestinfra.app 2. Open Master Data → Consumer Data 3. Confirm title is Consumer Data and Advanced Filters is ON unless the case says otherwise 4. Open Connection Status, pick Connected (or live value) 5. Apply | F30: Connection Status lookup | G30: Grid only shows that status. Opening a row shows the matching header badge (e.g. Connected). | I30: Not Executed | J30: High | K30: Positive | L30: API + UI click | M30: Partial | N30: GET /indore/master-data/consumer-master-data?connectionStatusTblRefId= | O30: src/modules/MASTER-DATA/tests/consumer-master.spec.ts | npm run test:master-data
A31: IND-CMD-0021 | B31: Category | C31: All Categories | D31: Filter by consumer category | E31: 1. Login as Super Admin on https://indore.bestinfra.app 2. Open Master Data → Consumer Data 3. Confirm title is Consumer Data and Advanced Filters is ON unless the case says otherwise 4. Open All Categories, pick a category 5. Apply 6. Check Category column | F31: All Categories placeholder = no category filter | G31: Rows match the category. Clearing back to All Categories + Apply restores mixed categories. | I31: Not Executed | J31: High | K31: Positive | L31: API + UI click | M31: Partial | N31: GET /indore/master-data/consumer-master-data?categoryTblRefId= | O31: src/modules/MASTER-DATA/tests/consumer-master.spec.ts | npm run test:master-data
A32: IND-CMD-0022 | B32: Device Manufacturer | C32: Device Manufacturer | D32: Filter by Device Manufacturer / OEM | E32: 1. Login as Super Admin on https://indore.bestinfra.app 2. Open Master Data → Consumer Data 3. Confirm title is Consumer Data and Advanced Filters is ON unless the case says otherwise 4. Pick a manufacturer (e.g. L&T if listed) 5. Apply 6. Check Meter Make | F32: Device Manufacturer lookup | G32: Meter Make on visible rows matches the manufacturer. Empty OEM list is a fail only if lookups loaded. | I32: Not Executed | J32: Medium | K32: Positive | L32: API + UI click | M32: Partial | N32: GET /indore/master-data/consumer-master-data?deviceManufacturerTblRefId= | O32: src/modules/MASTER-DATA/tests/consumer-master.spec.ts | npm run test:master-data
A33: IND-CMD-0023 | B33: Payment Contract | C33: Payment Contract | D33: Filter by Payment Contract | E33: 1. Login as Super Admin on https://indore.bestinfra.app 2. Open Master Data → Consumer Data 3. Confirm title is Consumer Data and Advanced Filters is ON unless the case says otherwise 4. Pick a payment contract 5. Apply | F33: Payment Contract lookup | G33: Grid refreshes to that contract set. Reset Filters clears the dropdown back to placeholder. | I33: Not Executed | J33: Medium | K33: Positive | L33: API + UI click | M33: Partial | N33: GET /indore/master-data/consumer-master-data?paymentContractTblRefId= | O33: src/modules/MASTER-DATA/tests/consumer-master.spec.ts | npm run test:master-data
A34: IND-CMD-0024 | B34: Filters | C34: Apply Filters without changing anything | D34: Apply with defaults does not error | E34: 1. Login as Super Admin on https://indore.bestinfra.app 2. Open Master Data → Consumer Data 3. Confirm title is Consumer Data and Advanced Filters is ON unless the case says otherwise 4. Click Apply Filters with all placeholders and All radio | F34: No extra criteria | G34: Grid reloads successfully. Total stays the unfiltered master count (or assigned-scope count). No empty-state flash that sticks. | I34: Not Executed | J34: Medium | K34: Edge | L34: API + UI click | M34: Partial | N34: GET /indore/master-data/consumer-master-data default Apply | O34: src/modules/MASTER-DATA/tests/consumer-master.spec.ts | npm run test:master-data
A35: IND-CMD-0025 | B35: Filters | C35: Combined filters | D35: Multiple filters together AND the result set | E35: 1. Login as Super Admin on https://indore.bestinfra.app 2. Open Master Data → Consumer Data 3. Confirm title is Consumer Data and Advanced Filters is ON unless the case says otherwise 4. Set hierarchy + Meter Phase + Category + Online 5. Apply | F35: Multi-filter AND | G35: Every visible row satisfies all applied criteria. Total is ≤ each single-filter total. Impossible combo shows filtered empty state 'No data available'. | I35: Not Executed | J35: Critical | K35: Positive | L35: API + UI click | M35: Partial | N35: GET /indore/master-data/consumer-master-data combined filters AND | O35: src/modules/MASTER-DATA/tests/consumer-master.spec.ts | npm run test:master-data
A36: 4. COMMUNICATION STATUS, RESET, FILTER TOGGLE
A37: IND-CMD-0026 | B37: Online status | C37: All radio | D37: All is the default communication status | E37: 1. Login as Super Admin on https://indore.bestinfra.app 2. Open Master Data → Consumer Data 3. Confirm title is Consumer Data and Advanced Filters is ON unless the case says otherwise 4. Observe All / Online / Offline | F37: All selected with green check | G37: All is selected on load. Grid includes both communicating and non-communicating consumers. | I37: Not Executed | J37: High | K37: UI | L37: UI only | M37: Gap (UI) | N37: — | O37: All radio default
A38: IND-CMD-0027 | B38: Online status | C38: Online radio + Apply Filters | D38: Online filter shows only communicating consumers | E38: 1. Login as Super Admin on https://indore.bestinfra.app 2. Open Master Data → Consumer Data 3. Confirm title is Consumer Data and Advanced Filters is ON unless the case says otherwise 4. Select Online 5. Apply Filters | F38: All | Online | Offline | G38: Pagination total is the Online subset. Rows are communicating. Changing radio without Apply must not silently keep old results if the product requires Apply — follow the live rule and note it. | I38: Not Executed | J38: Critical | K38: Positive | L38: API + UI click | M38: Partial | N38: GET /indore/master-data/consumer-master-data communicationStatus=Online | O38: src/modules/MASTER-DATA/tests/consumer-master.spec.ts | npm run test:master-data
A39: IND-CMD-0028 | B39: Online status | C39: Offline radio + Apply Filters | D39: Offline filter shows only non-communicating consumers | E39: 1. Login as Super Admin on https://indore.bestinfra.app 2. Open Master Data → Consumer Data 3. Confirm title is Consumer Data and Advanced Filters is ON unless the case says otherwise 4. Select Offline 5. Apply Filters | F39: Offline | G39: Grid is the Offline subset. Opening a consumer still loads the dashboard (dashboard may show delayed/failed comms). Not the full 126743 list. | I39: Not Executed | J39: Critical | K39: Positive | L39: API + UI click | M39: Partial | N39: GET /indore/master-data/consumer-master-data communicationStatus=Offline | O39: src/modules/MASTER-DATA/tests/consumer-master.spec.ts | npm run test:master-data
A40: IND-CMD-0029 | B40: Reset | C40: Reset Filters | D40: Reset Filters clears every criterion including radios and search | E40: 1. Login as Super Admin on https://indore.bestinfra.app 2. Open Master Data → Consumer Data 3. Confirm title is Consumer Data and Advanced Filters is ON unless the case says otherwise 4. Set search + hierarchy + a dropdown + Offline 5. Apply 6. Click Reset Filters | F40: Reset Filters button | G40: Search is empty. Dropdowns return to placeholders (Hierarchy Type, Select Hierarchy, Meter Type default, All Meter Phases, Connection Status, All Categories, Device Manufacturer, Payment Contract). Radio returns to All. Grid returns to the unfiltered master total. | I40: Not Executed | J40: Critical | K40: Positive | L40: UI only | M40: Gap (UI) | N40: — | O40: Reset Filters control
A41: IND-CMD-0030 | B41: Filters | C41: Advanced Filters toggle | D41: Turning Advanced Filters OFF hides the panel without losing the grid | E41: 1. Login as Super Admin on https://indore.bestinfra.app 2. Open Master Data → Consumer Data 3. Confirm title is Consumer Data and Advanced Filters is ON unless the case says otherwise 4. Apply a filter so the total changes 5. Toggle Advanced Filters OFF 6. Toggle ON again | F41: Toggle switch top-right of filter panel | G41: Panel collapses/hides. Grid remains visible. Turning ON again still shows the last applied filters (or product-documented default). Page does not reload to a blank state. | I41: Not Executed | J41: Medium | K41: UI | L41: UI only | M41: Gap (UI) | N41: — | O41: Advanced Filters toggle
A42: IND-CMD-0031 | B42: Filters | C42: Apply Filters | D42: Impossible filter combo shows filtered empty state | E42: 1. Login as Super Admin on https://indore.bestinfra.app 2. Open Master Data → Consumer Data 3. Confirm title is Consumer Data and Advanced Filters is ON unless the case says otherwise 4. Combine filters that cannot match (e.g. Offline + a rare category + a tight hierarchy) 5. Apply | F42: Filtered empty copy | G42: Title 'No data available'. Description asks to choose different filters. Clear All Filters action is offered. Not the search empty-state copy. | I42: Not Executed | J42: High | K42: Negative | L42: API + UI click | M42: Partial | N42: GET /indore/master-data/consumer-master-data empty filtered page | O42: src/modules/MASTER-DATA/tests/consumer-master.spec.ts | npm run test:master-data
...

Sheet SNAPSHOT
A1: Screenshot baseline 09-Sep-2026 — use live UI values at execution; this sheet is the audit reference
A3: Consumer Data list
A4: Metric | B4: Value | C4: Note | D4: Check
A5: Pagination total | B5: 126743 | C5: Showing 1-10 of 126743 | D5: Master total
A6: Page size | B6: 10 | C6: 10 / page | D6: Default
A7: Last page | B7: 12675 | C7: 126743 / 10 = 12674.3 → 12675 pages | D7: Ceil
A8: Circle (visible rows) | B8: Indore City Circle | C8: All visible sample rows | D8: Hierarchy
A10: Pages check | B10: =ROUNDUP(B5/B6,0) | C10: Must equal last page B7 | D10: =IF(B10=B7,"PASS","FAIL — pages "&B10)
A12: Anchor consumer (list → dashboard)
A13: Field | B13: Value | C13: Where | D13: Must match
A14: Consumer Name | B14: Babulal Nandram | C14: Grid row 1 / dashboard header | D14: Yes
A15: IVRS No. | B15: N3968028469 | C15: Dashboard badge | D15: Yes
A16: Consumer ID (sample) | B16: MML0000205 | C16: Grid CID column (row 1 in shot) | D16: List vs profile
A17: Meter Sl No. | B17: 88017671 | C17: Real-Time Power + Meter Events | D17: Yes
A18: Status | B18: Connected | C18: Dashboard badge | D18: Vs Connection Status filter
A19: DTR Code (sample) | B19: MM521 / 34SO19 | C19: Grid DTR Code | D19: Opens /dtr/{code}
A22: Consumer Dashboard KPIs
A23: KPI | B23: Value | C23: Footer | D23: Type
A24: Maximum Demand (kVA) | B24: 0.2 kVA | C24: No previous-month data | D24: Decimal
A25: Maximum Demand (kW) | B25: 0.2 kW | C25: No previous-month data | D25: Decimal
A26: Neutral Current | B26: 0.22 Amps | C26: No previous-month data | D26: Decimal
A27: Overall PF | B27: -0.97 | C27: No previous-month data | D27: Negative allowed
A28: Frequency | B28: 49.9 Hz | C28: No previous-month data | D28: Decimal
A29: Resolved Events | B29: 3 | C29: No change vs last month | D29: Integer
A30: Pending Events | B30: 2 | C30: No change vs last month | D30: Integer
A31: Avg Resolution Time | B31: 5m | C31: No previous-month data | D31: Duration
A32: Daily Consumption | B32: 1.9 | C32: Previous day: 1.9 kWh | D32: kWh
A33: Monthly Consumption | B33: 57.15 | C33: Last month: 74.37 kWh | D33: kWh
A34: Total Outstanding | B34: ₹0 | C34: Current dues | D34: Currency
A35: Bill Status | B35: Unknown | C35: Current status | D35: String
A37: Resolved + Pending (snapshot events table) | B37: =B29+B30 | C37: Must equal Meter Events total B44 if same window | D37: =IF(B37=B44,"PASS","CHECK window — snapshot events=5")
A39: Real-Time / Live Load / Energy Flow
A40: Metric | B40: Value | C40: Note | D40: Check
A41: R-Phase V / I / PF | B41: 249.38 V · 0.22 A · -0.97 | C41: Active phase | D41: PF sign matches KPI
A42: Y-Phase / B-Phase | B42: -- / -- / -- | C42: 1-phase | D42: Not 0.00
A43: Live Load Total | B43: 0.08 | C43: Active 0.04 + Apparent 0.04 + Reactive 0 | D43: Sum
A44: Meter Events rows | B44: 5 | C44: Showing 1-5 of 5 | D44: Restored 3 + Pending 2
A45: RT timestamp | B45: 30 Nov 2025 11:45 PM | C45: Real-Time header | D45: DEF-CMD-001 if ≠ live load
A46: Live Load last comm | B46: 1 Dec 2025 11:46 PM | C46: Live Load subtitle | D46: DEF-CMD-001
A48: Live Load parts | B48: 0.08 | C48: Must equal Live Load Total B43 | D48: =IF(ABS(B48-B43)<0.0001,"PASS","FAIL")
...
